Workbook
Name _ftn1: params!$AC$40
Name _ftn2: params!$AC$41
Name _ftnref1: params!$AG$15
Name _ftnref2: params!$AE$19
Name CC_options: [1]parameters!$B$119:$B$128
Name End_year: '[1]setup & summary'!$B$4
Name fNRB: params!$D$40
Name Intervention1_end: '[1]setup & summary'!$E$4
Name Intervention1_start: '[1]setup & summary'!$E$3
Name Intervention2_end: '[1]setup & summary'!$F$4
Name Intervention2_start: '[1]setup & summary'!$F$3
Name Intervention3_end: '[1]setup & summary'!$G$4
Name Intervention3_start: '[1]setup & summary'!$G$3
Name List_years: #REF!
Name rural_hh: [1]parameters!$Z$2
Name start_year: '[1]setup & summary'!$B$3
Name UGX_USD: [1]parameters!$L$118
Name UGX_USD: params!$AC$2
Name urban_hh: [1]parameters!$Z$3

Sheet Read Me
A1: This is a prototype tool for simulating and tracking fuel consumption and emissions associated with household fuel choice trajectories.
A3: Worksheet
A4: Summary | B4: This sheet summarises outputs for select years.
A5: BAU_Scenario | B5: This sheet shows the percentages and number of households cooking with each primary fuel/stove combination. Data in 2020, 2021 and 2024 are based on actual data points from recent national survey (see "params" worksheet. Data for 2050 are from WHO. Other years are linear extrapolations.
A6: BAU_Fuel_cons | B6: This sheet shows fuel consumption, which is derived by multiplying the data from the "BAU_scenario" worksheet by fuel consumption per household, which is listed in the "params" worksheet.
A7: BAU_emissions | B7: This sheet shows emissions of GHGs and SLCPs, which are derived by multiplying the data from the "BAU_Fuel_cons" worksheet by fuel-specific emission factors, which are listed in the "efs" worksheet. It also accounts for fNRB, which is taken from the latest MoFuSS analysis, and is also listed on the "params" sheet.
A8: NICCS_scenario | B8: This sheet shows the percentages and number of households cooking with each primary fuel/stove combination and meeting NICCS 2040 targets. Data match BAU through 2025. Total population matches BAU.
A9: NICCS_Fuel_cons | B9: This sheet shows fuel consumption, which is derived by multiplying the data from the "NICCS_scenario" worksheet by fuel consumption per household, which is listed in the "params" worksheet.
A10: NICCS_emissions | B10: This sheet shows emissions of GHGs and SLCPs, which are derived by multiplying the data from the "NICCS_Fuel_cons" worksheet by fuel-specific emission factors, which are listed in the "efs" worksheet. It also accounts for fNRB, which is taken from the latest MoFuSS analysis, and is also listed on the "params" sheet. We assume fNRB doesn't change, though it would likely be lower from reduced woodfuel demand.
A11: Cost_diff | B11: This sheet shows the cost differential between the two trajectories.
A12: Population | B12: This sheet shows population projections from WHO and household size data from DHS and UBOS. The projections in the BAU_scenario and NICCS_scenario worksheets use WHO projections and DHS and UBOS household sizes to estimate no. of rural and urban households through 2050.
A13: params | B13: This sheet lists key input parameters including fuel choice data from UBOS surveys, tax rates, fuel consumption per capita, fuel unit costs, and calorific values.
A14: efs | B14: This sheet shows fuel and stove-specific emission factors used to estimate emissions.

Sheet Summary
A1: No. of fuel users | C1: 2030 | E1: 2040 | I1: BAU
C2: BAU | E2: BAU
A3: overall | B3: fuelwood | C3: =_xlfn.XLOOKUP(C$1,BAU_Scenario!$N$1:$AS$1,BAU_Scenario!$N2:$AS2,0) -> 16.659931 | E3: =_xlfn.XLOOKUP(E$1,BAU_Scenario!$N$1:$AS$1,BAU_Scenario!$N2:$AS2,0) -> 13.480129
A4: overall | B4: charcoal | C4: =_xlfn.XLOOKUP(C$1,BAU_Scenario!$N$1:$AS$1,BAU_Scenario!$N3:$AS3,0) -> 19.130147 | E4: =_xlfn.XLOOKUP(E$1,BAU_Scenario!$N$1:$AS$1,BAU_Scenario!$N3:$AS3,0) -> 32.459671
A5: overall | B5: Imp_fuelwood | C5: =_xlfn.XLOOKUP(C$1,BAU_Scenario!$N$1:$AS$1,BAU_Scenario!$N4:$AS4,0) -> 0.44835392 | E5: =_xlfn.XLOOKUP(E$1,BAU_Scenario!$N$1:$AS$1,BAU_Scenario!$N4:$AS4,0) -> 1.0060545
A6: overall | B6: Imp_charcoal | C6: =_xlfn.XLOOKUP(C$1,BAU_Scenario!$N$1:$AS$1,BAU_Scenario!$N5:$AS5,0) -> 0.14945131 | E6: =_xlfn.XLOOKUP(E$1,BAU_Scenario!$N$1:$AS$1,BAU_Scenario!$N5:$AS5,0) -> 0.3353515
A7: overall | B7: Gas | C7: =_xlfn.XLOOKUP(C$1,BAU_Scenario!$N$1:$AS$1,BAU_Scenario!$N6:$AS6,0) -> 0.076179559 | E7: =_xlfn.XLOOKUP(E$1,BAU_Scenario!$N$1:$AS$1,BAU_Scenario!$N6:$AS6,0) -> 0.053954537
A8: overall | B8: kerosene | C8: =_xlfn.XLOOKUP(C$1,BAU_Scenario!$N$1:$AS$1,BAU_Scenario!$N7:$AS7,0) -> 0 | E8: =_xlfn.XLOOKUP(E$1,BAU_Scenario!$N$1:$AS$1,BAU_Scenario!$N7:$AS7,0) -> 0
A9: overall | B9: electric | C9: =_xlfn.XLOOKUP(C$1,BAU_Scenario!$N$1:$AS$1,BAU_Scenario!$N8:$AS8,0) -> 0.79918953 | E9: =_xlfn.XLOOKUP(E$1,BAU_Scenario!$N$1:$AS$1,BAU_Scenario!$N8:$AS8,0) -> 0.56489882
A10: overall | B10: pellets | C10: =_xlfn.XLOOKUP(C$1,BAU_Scenario!$N$1:$AS$1,BAU_Scenario!$N9:$AS9,0) -> 0 | E10: =_xlfn.XLOOKUP(E$1,BAU_Scenario!$N$1:$AS$1,BAU_Scenario!$N9:$AS9,0) -> 0
A11: overall | B11: ethanol | C11: =_xlfn.XLOOKUP(C$1,BAU_Scenario!$N$1:$AS$1,BAU_Scenario!$N10:$AS10,0) -> 0 | E11: =_xlfn.XLOOKUP(E$1,BAU_Scenario!$N$1:$AS$1,BAU_Scenario!$N10:$AS10,0) -> 0
A12: overall | B12: biogas | C12: =_xlfn.XLOOKUP(C$1,BAU_Scenario!$N$1:$AS$1,BAU_Scenario!$N11:$AS11,0) -> 0 | E12: =_xlfn.XLOOKUP(E$1,BAU_Scenario!$N$1:$AS$1,BAU_Scenario!$N11:$AS11,0) -> 0
A13: overall | B13: other | C13: =_xlfn.XLOOKUP(C$1,BAU_Scenario!$N$1:$AS$1,BAU_Scenario!$N12:$AS12,0) -> 0.10929426 | E13: =_xlfn.XLOOKUP(E$1,BAU_Scenario!$N$1:$AS$1,BAU_Scenario!$N12:$AS12,0) -> 0.065045042
A14: rural | B14: fuelwood | C14: =_xlfn.XLOOKUP(C$1,BAU_Scenario!$N$1:$AS$1,BAU_Scenario!$N13:$AS13,0) -> 14.408239 | E14: =_xlfn.XLOOKUP(E$1,BAU_Scenario!$N$1:$AS$1,BAU_Scenario!$N13:$AS13,0) -> 11.878574
... A35: urban | B35: other | C35: =_xlfn.XLOOKUP(C$1,BAU_Scenario!$N$1:$AS$1,BAU_Scenario!$N34:$AS34,0) -> 0 | E35: =_xlfn.XLOOKUP(E$1,BAU_Scenario!$N$1:$AS$1,BAU_Scenario!$N34:$AS34,0) -> 0
B36: Woodfuel total | C36: =SUM(C3:C6) -> 36.387884 | E36: =SUM(E3:E6) -> 47.281207
A37: clean | B37: overall | C37: =SUM(C5:C7,C9:C12)/SUM(C3:C13) -> 0.039418622 | E37: =SUM(E5:E7,E9:E12)/SUM(E3:E13) -> 0.040868447
B38: rural | C38: =SUM(C16:C18,C20:C23)/SUM(C14:C24) -> 0.0015472441 | E38: =SUM(E16:E18,E20:E23)/SUM(E14:E24) -> 0.00077646763
B39: urban | C39: =SUM(C27:C29,C31:C34)/SUM(C25:C35) -> 0.087838594 | E39: =SUM(E27:E29,E31:E34)/SUM(E25:E35) -> 0.084038773
A40: Energy consumption (PJ) | C40: BAU | E40: BAU
A41: overall | B41: fuelwood | C41: =BAU_Fuel_cons!Y40 -> 0 | E41: =BAU_Fuel_cons!AI40 -> 0
A42: overall | B42: charcoal | C42: =BAU_Fuel_cons!Y41 -> 0 | E42: =BAU_Fuel_cons!AI41 -> 0
A43: overall | B43: Imp_fuelwood | C43: =BAU_Fuel_cons!Y42 -> 0 | E43: =BAU_Fuel_cons!AI42 -> 0
A44: overall | B44: Imp_charcoal | C44: =BAU_Fuel_cons!Y43 -> 0 | E44: =BAU_Fuel_cons!AI43 -> 0
A45: overall | B45: Gas | C45: =BAU_Fuel_cons!Y44 -> 0 | E45: =BAU_Fuel_cons!AI44 -> 0
A46: overall | B46: kerosene | C46: =BAU_Fuel_cons!Y45 -> 0 | E46: =BAU_Fuel_cons!AI45 -> 0
A47: overall | B47: electric | C47: =BAU_Fuel_cons!Y46 -> 0 | E47: =BAU_Fuel_cons!AI46 -> 0
A48: overall | B48: pellets | C48: =BAU_Fuel_cons!Y47 -> 0 | E48: =BAU_Fuel_cons!AI47 -> 0
A49: overall | B49: ethanol | C49: =BAU_Fuel_cons!Y48 -> 0 | E49: =BAU_Fuel_cons!AI48 -> 0
A50: overall | B50: biogas | C50: =BAU_Fuel_cons!Y49 -> 0 | E50: =BAU_Fuel_cons!AI49 -> 0
A51: overall | B51: other | C51: =BAU_Fuel_cons!Y50 -> 0 | E51: =BAU_Fuel_cons!AI50 -> 0
A52: rural | B52: fuelwood | C52: =BAU_Fuel_cons!Y51 -> 0 | E52: =BAU_Fuel_cons!AI51 -> 0
... A73: urban | B73: other | C73: =BAU_Fuel_cons!Y72 -> 0 | E73: =BAU_Fuel_cons!AI72 -> 0
B74: Woodfuel total | C74: =SUM(C41:C44) -> 0 | E74: =SUM(E41:E44) -> 0
A75: clean | B75: overall | C75: =SUM(C41:C51) -> 0 | E75: =SUM(E41:E51) -> 0
B76: rural | C76: =SUM(C52:C62) -> 0 | E76: =SUM(E52:E62) -> 0
B77: urban | C77: =SUM(C63:C73) -> 0 | E77: =SUM(E63:E73) -> 0
A78: Emissions (CO2e) | C78: BAU | E78: BAU
A79: overall | B79: fuelwood | C79: =BAU_emissions!P2 -> 7947.7629 | E79: =BAU_emissions!Z2 -> 6430.8112
A80: overall | B80: charcoal | C80: =BAU_emissions!P3 -> 12446.056 | E80: =BAU_emissions!Z3 -> 21118.232
...

Sheet EED_BAU_KNBS-pop
A1: FROM EED | B1: Fuel | C1: Scenario | D1: unit | E1: 2019 | F1: 2020 | G1: 2021 | H1: 2022 | I1: 2023 | J1: 2024 | K1: 2025 | L1: 2026 | M1: 2027 | N1: 2028 | O1: 2029 | P1: 2030 | Q1: 2031 | R1: 2032 | S1: 2033 | T1: 2034 | U1: 2035 | V1: 2036 | W1: 2037 | X1: 2038 | Y1: 2039 | Z1: 2040 | AA1: 2041 | AB1: 2042 | AC1: 2043 | AD1: 2044 | AE1: 2045 | AF1: 2046 | AG1: 2047 | AH1: 2048 | AI1: 2049 | AJ1: 2050 | AK1: Comments
A2: overall | B2: biomass | C2: BAU-S | D2: M hh | E2: {=E38*_xlfn.XLOOKUP(1,(Population!$A:$A=E$1)*(Population!$B:$B=$A2),Population!$F:$F)/10^3} -> #REF! | F2: {=F38*_xlfn.XLOOKUP(1,(Population!$A:$A=F$1)*(Population!$B:$B=$A2),Population!$F:$F)/10^3} -> #REF! | G2: {=G38*_xlfn.XLOOKUP(1,(Population!$A:$A=G$1)*(Population!$B:$B=$A2),Population!$F:$F)/10^3} -> #REF! | H2: {=H38*_xlfn.XLOOKUP(1,(Population!$A:$A=H$1)*(Population!$B:$B=$A2),Population!$F:$F)/10^3} -> #REF! | I2: {=I38*_xlfn.XLOOKUP(1,(Population!$A:$A=I$1)*(Population!$B:$B=$A2),Population!$F:$F)/10^3} -> #REF! | J2: {=J38*_xlfn.XLOOKUP(1,(Population!$A:$A=J$1)*(Population!$B:$B=$A2),Population!$F:$F)/10^3} -> #REF! | K2: {=K38*_xlfn.XLOOKUP(1,(Population!$A:$A=K$1)*(Population!$B:$B=$A2),Population!$F:$F)/10^3} -> #REF! | L2: {=L38*_xlfn.XLOOKUP(1,(Population!$A:$A=L$1)*(Population!$B:$B=$A2),Population!$F:$F)/10^3} -> #REF! | ... AJ2: {=AJ38*_xlfn.XLOOKUP(1,(Population!$A:$A=AJ$1)*(Population!$B:$B=$A2),Population!$F:$F)/10^3} -> #N/A
A3: overall | B3: charcoal | C3: BAU-S | D3: M hh | E3: {=E39*_xlfn.XLOOKUP(1,(Population!$A:$A=E$1)*(Population!$B:$B=$A3),Population!$F:$F)/10^3} -> #REF! | F3: {=F39*_xlfn.XLOOKUP(1,(Population!$A:$A=F$1)*(Population!$B:$B=$A3),Population!$F:$F)/10^3} -> #REF! | G3: {=G39*_xlfn.XLOOKUP(1,(Population!$A:$A=G$1)*(Population!$B:$B=$A3),Population!$F:$F)/10^3} -> #REF! | H3: {=H39*_xlfn.XLOOKUP(1,(Population!$A:$A=H$1)*(Population!$B:$B=$A3),Population!$F:$F)/10^3} -> #REF! | I3: {=I39*_xlfn.XLOOKUP(1,(Population!$A:$A=I$1)*(Population!$B:$B=$A3),Population!$F:$F)/10^3} -> #REF! | J3: {=J39*_xlfn.XLOOKUP(1,(Population!$A:$A=J$1)*(Population!$B:$B=$A3),Population!$F:$F)/10^3} -> #REF! | K3: {=K39*_xlfn.XLOOKUP(1,(Population!$A:$A=K$1)*(Population!$B:$B=$A3),Population!$F:$F)/10^3} -> #REF! | L3: {=L39*_xlfn.XLOOKUP(1,(Population!$A:$A=L$1)*(Population!$B:$B=$A3),Population!$F:$F)/10^3} -> #REF! | ... AJ3: {=AJ39*_xlfn.XLOOKUP(1,(Population!$A:$A=AJ$1)*(Population!$B:$B=$A3),Population!$F:$F)/10^3} -> #N/A
A4: overall | B4: Imp_biomass | C4: BAU-S | D4: M hh | E4: {=E40*_xlfn.XLOOKUP(1,(Population!$A:$A=E$1)*(Population!$B:$B=$A4),Population!$F:$F)/10^3} -> #REF! | F4: {=F40*_xlfn.XLOOKUP(1,(Population!$A:$A=F$1)*(Population!$B:$B=$A4),Population!$F:$F)/10^3} -> #REF! | G4: {=G40*_xlfn.XLOOKUP(1,(Population!$A:$A=G$1)*(Population!$B:$B=$A4),Population!$F:$F)/10^3} -> #REF! | H4: {=H40*_xlfn.XLOOKUP(1,(Population!$A:$A=H$1)*(Population!$B:$B=$A4),Population!$F:$F)/10^3} -> #REF! | I4: {=I40*_xlfn.XLOOKUP(1,(Population!$A:$A=I$1)*(Population!$B:$B=$A4),Population!$F:$F)/10^3} -> #REF! | J4: {=J40*_xlfn.XLOOKUP(1,(Population!$A:$A=J$1)*(Population!$B:$B=$A4),Population!$F:$F)/10^3} -> #REF! | K4: {=K40*_xlfn.XLOOKUP(1,(Population!$A:$A=K$1)*(Population!$B:$B=$A4),Population!$F:$F)/10^3} -> #REF! | L4: {=L40*_xlfn.XLOOKUP(1,(Population!$A:$A=L$1)*(Population!$B:$B=$A4),Population!$F:$F)/10^3} -> #REF! | ... AJ4: {=AJ40*_xlfn.XLOOKUP(1,(Population!$A:$A=AJ$1)*(Population!$B:$B=$A4),Population!$F:$F)/10^3} -> #N/A
A5: overall | B5: Imp_charcoal | C5: BAU-S | D5: M hh | E5: {=E41*_xlfn.XLOOKUP(1,(Population!$A:$A=E$1)*(Population!$B:$B=$A5),Population!$F:$F)/10^3} -> #REF! | F5: {=F41*_xlfn.XLOOKUP(1,(Population!$A:$A=F$1)*(Population!$B:$B=$A5),Population!$F:$F)/10^3} -> #REF! | G5: {=G41*_xlfn.XLOOKUP(1,(Population!$A:$A=G$1)*(Population!$B:$B=$A5),Population!$F:$F)/10^3} -> #REF! | H5: {=H41*_xlfn.XLOOKUP(1,(Population!$A:$A=H$1)*(Population!$B:$B=$A5),Population!$F:$F)/10^3} -> #REF! | I5: {=I41*_xlfn.XLOOKUP(1,(Population!$A:$A=I$1)*(Population!$B:$B=$A5),Population!$F:$F)/10^3} -> #REF! | J5: {=J41*_xlfn.XLOOKUP(1,(Population!$A:$A=J$1)*(Population!$B:$B=$A5),Population!$F:$F)/10^3} -> #REF! | K5: {=K41*_xlfn.XLOOKUP(1,(Population!$A:$A=K$1)*(Population!$B:$B=$A5),Population!$F:$F)/10^3} -> #REF! | L5: {=L41*_xlfn.XLOOKUP(1,(Population!$A:$A=L$1)*(Population!$B:$B=$A5),Population!$F:$F)/10^3} -> #REF! | ... AJ5: {=AJ41*_xlfn.XLOOKUP(1,(Population!$A:$A=AJ$1)*(Population!$B:$B=$A5),Population!$F:$F)/10^3} -> #N/A
A6: overall | B6: Gas | C6: BAU-S | D6: M hh | E6: {=E42*_xlfn.XLOOKUP(1,(Population!$A:$A=E$1)*(Population!$B:$B=$A6),Population!$F:$F)/10^3} -> #N/A | F6: {=F42*_xlfn.XLOOKUP(1,(Population!$A:$A=F$1)*(Population!$B:$B=$A6),Population!$F:$F)/10^3} -> #N/A | G6: {=G42*_xlfn.XLOOKUP(1,(Population!$A:$A=G$1)*(Population!$B:$B=$A6),Population!$F:$F)/10^3} -> #N/A | H6: {=H42*_xlfn.XLOOKUP(1,(Population!$A:$A=H$1)*(Population!$B:$B=$A6),Population!$F:$F)/10^3} -> #N/A | I6: {=I42*_xlfn.XLOOKUP(1,(Population!$A:$A=I$1)*(Population!$B:$B=$A6),Population!$F:$F)/10^3} -> #N/A | J6: {=J42*_xlfn.XLOOKUP(1,(Population!$A:$A=J$1)*(Population!$B:$B=$A6),Population!$F:$F)/10^3} -> #N/A | K6: {=K42*_xlfn.XLOOKUP(1,(Population!$A:$A=K$1)*(Population!$B:$B=$A6),Population!$F:$F)/10^3} -> #N/A | L6: {=L42*_xlfn.XLOOKUP(1,(Population!$A:$A=L$1)*(Population!$B:$B=$A6),Population!$F:$F)/10^3} -> #N/A | ... AJ6: {=AJ42*_xlfn.XLOOKUP(1,(Population!$A:$A=AJ$1)*(Population!$B:$B=$A6),Population!$F:$F)/10^3} -> #N/A
A7: overall | B7: kerosene | C7: BAU-S | D7: M hh | E7: {=E43*_xlfn.XLOOKUP(1,(Population!$A:$A=E$1)*(Population!$B:$B=$A7),Population!$F:$F)/10^3} -> #N/A | F7: {=F43*_xlfn.XLOOKUP(1,(Population!$A:$A=F$1)*(Population!$B:$B=$A7),Population!$F:$F)/10^3} -> #N/A | G7: {=G43*_xlfn.XLOOKUP(1,(Population!$A:$A=G$1)*(Population!$B:$B=$A7),Population!$F:$F)/10^3} -> #N/A | H7: {=H43*_xlfn.XLOOKUP(1,(Population!$A:$A=H$1)*(Population!$B:$B=$A7),Population!$F:$F)/10^3} -> #N/A | I7: {=I43*_xlfn.XLOOKUP(1,(Population!$A:$A=I$1)*(Population!$B:$B=$A7),Population!$F:$F)/10^3} -> #N/A | J7: {=J43*_xlfn.XLOOKUP(1,(Population!$A:$A=J$1)*(Population!$B:$B=$A7),Population!$F:$F)/10^3} -> #N/A | K7: {=K43*_xlfn.XLOOKUP(1,(Population!$A:$A=K$1)*(Population!$B:$B=$A7),Population!$F:$F)/10^3} -> #N/A | L7: {=L43*_xlfn.XLOOKUP(1,(Population!$A:$A=L$1)*(Population!$B:$B=$A7),Population!$F:$F)/10^3} -> #N/A | ... AJ7: {=AJ43*_xlfn.XLOOKUP(1,(Population!$A:$A=AJ$1)*(Population!$B:$B=$A7),Population!$F:$F)/10^3} -> #N/A
A8: overall | B8: electric | C8: BAU-S | D8: M hh | E8: {=E44*_xlfn.XLOOKUP(1,(Population!$A:$A=E$1)*(Population!$B:$B=$A8),Population!$F:$F)/10^3} -> #N/A | F8: {=F44*_xlfn.XLOOKUP(1,(Population!$A:$A=F$1)*(Population!$B:$B=$A8),Population!$F:$F)/10^3} -> #N/A | G8: {=G44*_xlfn.XLOOKUP(1,(Population!$A:$A=G$1)*(Population!$B:$B=$A8),Population!$F:$F)/10^3} -> #N/A | H8: {=H44*_xlfn.XLOOKUP(1,(Population!$A:$A=H$1)*(Population!$B:$B=$A8),Population!$F:$F)/10^3} -> #N/A | I8: {=I44*_xlfn.XLOOKUP(1,(Population!$A:$A=I$1)*(Population!$B:$B=$A8),Population!$F:$F)/10^3} -> #N/A | J8: {=J44*_xlfn.XLOOKUP(1,(Population!$A:$A=J$1)*(Population!$B:$B=$A8),Population!$F:$F)/10^3} -> #N/A | K8: {=K44*_xlfn.XLOOKUP(1,(Population!$A:$A=K$1)*(Population!$B:$B=$A8),Population!$F:$F)/10^3} -> #N/A | L8: {=L44*_xlfn.XLOOKUP(1,(Population!$A:$A=L$1)*(Population!$B:$B=$A8),Population!$F:$F)/10^3} -> #N/A | ... AJ8: {=AJ44*_xlfn.XLOOKUP(1,(Population!$A:$A=AJ$1)*(Population!$B:$B=$A8),Population!$F:$F)/10^3} -> #N/A
A9: overall | B9: pellets | C9: BAU-S | D9: M hh | E9: {=E45*_xlfn.XLOOKUP(1,(Population!$A:$A=E$1)*(Population!$B:$B=$A9),Population!$F:$F)/10^3} -> #N/A | F9: {=F45*_xlfn.XLOOKUP(1,(Population!$A:$A=F$1)*(Population!$B:$B=$A9),Population!$F:$F)/10^3} -> #N/A | G9: {=G45*_xlfn.XLOOKUP(1,(Population!$A:$A=G$1)*(Population!$B:$B=$A9),Population!$F:$F)/10^3} -> #N/A | H9: {=H45*_xlfn.XLOOKUP(1,(Population!$A:$A=H$1)*(Population!$B:$B=$A9),Population!$F:$F)/10^3} -> #N/A | I9: {=I45*_xlfn.XLOOKUP(1,(Population!$A:$A=I$1)*(Population!$B:$B=$A9),Population!$F:$F)/10^3} -> #N/A | J9: {=J45*_xlfn.XLOOKUP(1,(Population!$A:$A=J$1)*(Population!$B:$B=$A9),Population!$F:$F)/10^3} -> #N/A | K9: {=K45*_xlfn.XLOOKUP(1,(Population!$A:$A=K$1)*(Population!$B:$B=$A9),Population!$F:$F)/10^3} -> #N/A | L9: {=L45*_xlfn.XLOOKUP(1,(Population!$A:$A=L$1)*(Population!$B:$B=$A9),Population!$F:$F)/10^3} -> #N/A | ... AJ9: {=AJ45*_xlfn.XLOOKUP(1,(Population!$A:$A=AJ$1)*(Population!$B:$B=$A9),Population!$F:$F)/10^3} -> #N/A
A10: overall | B10: ethanol | C10: BAU-S | D10: M hh | E10: {=E46*_xlfn.XLOOKUP(1,(Population!$A:$A=E$1)*(Population!$B:$B=$A10),Population!$F:$F)/10^3} -> #N/A | F10: {=F46*_xlfn.XLOOKUP(1,(Population!$A:$A=F$1)*(Population!$B:$B=$A10),Population!$F:$F)/10^3} -> #N/A | G10: {=G46*_xlfn.XLOOKUP(1,(Population!$A:$A=G$1)*(Population!$B:$B=$A10),Population!$F:$F)/10^3} -> #N/A | H10: {=H46*_xlfn.XLOOKUP(1,(Population!$A:$A=H$1)*(Population!$B:$B=$A10),Population!$F:$F)/10^3} -> #N/A | I10: {=I46*_xlfn.XLOOKUP(1,(Population!$A:$A=I$1)*(Population!$B:$B=$A10),Population!$F:$F)/10^3} -> #N/A | J10: {=J46*_xlfn.XLOOKUP(1,(Population!$A:$A=J$1)*(Population!$B:$B=$A10),Population!$F:$F)/10^3} -> #N/A | K10: {=K46*_xlfn.XLOOKUP(1,(Population!$A:$A=K$1)*(Population!$B:$B=$A10),Population!$F:$F)/10^3} -> #N/A | L10: {=L46*_xlfn.XLOOKUP(1,(Population!$A:$A=L$1)*(Population!$B:$B=$A10),Population!$F:$F)/10^3} -> #N/A | ... AJ10: {=AJ46*_xlfn.XLOOKUP(1,(Population!$A:$A=AJ$1)*(Population!$B:$B=$A10),Population!$F:$F)/10^3} -> #N/A
A11: overall | B11: biogas | C11: BAU-S | D11: M hh | E11: {=E47*_xlfn.XLOOKUP(1,(Population!$A:$A=E$1)*(Population!$B:$B=$A11),Population!$F:$F)/10^3} -> #N/A | F11: {=F47*_xlfn.XLOOKUP(1,(Population!$A:$A=F$1)*(Population!$B:$B=$A11),Population!$F:$F)/10^3} -> #N/A | G11: {=G47*_xlfn.XLOOKUP(1,(Population!$A:$A=G$1)*(Population!$B:$B=$A11),Population!$F:$F)/10^3} -> #N/A | H11: {=H47*_xlfn.XLOOKUP(1,(Population!$A:$A=H$1)*(Population!$B:$B=$A11),Population!$F:$F)/10^3} -> #N/A | I11: {=I47*_xlfn.XLOOKUP(1,(Population!$A:$A=I$1)*(Population!$B:$B=$A11),Population!$F:$F)/10^3} -> #N/A | J11: {=J47*_xlfn.XLOOKUP(1,(Population!$A:$A=J$1)*(Population!$B:$B=$A11),Population!$F:$F)/10^3} -> #N/A | K11: {=K47*_xlfn.XLOOKUP(1,(Population!$A:$A=K$1)*(Population!$B:$B=$A11),Population!$F:$F)/10^3} -> #N/A | L11: {=L47*_xlfn.XLOOKUP(1,(Population!$A:$A=L$1)*(Population!$B:$B=$A11),Population!$F:$F)/10^3} -> #N/A | ... AJ11: {=AJ47*_xlfn.XLOOKUP(1,(Population!$A:$A=AJ$1)*(Population!$B:$B=$A11),Population!$F:$F)/10^3} -> #N/A
A12: overall | B12: other | C12: BAU-S | D12: M hh | E12: 0.012360446 | F12: 0.012599688 | G12: 0.012839977 | H12: 0.013081829 | I12: 0.013324982 | J12: 0.013568963 | K12: 0.013813361 | L12: 0.014057381 | M12: 0.01430154 | N12: 0.014545575 | O12: 0.014789195 | P12: 0.015032073 | Q12: 0.015273893 | R12: 0.015514399 | S12: 0.015752977 | T12: 0.015988889 | U12: 0.016221545 | V12: 0.016451106 | W12: 0.016676945 | X12: 0.016898909 | Y12: 0.017116915 | Z12: 0.017330878 | AA12: 0.017541769 | AB12: 0.017748352 | AC12: 0.017950569 | AD12: 0.018148383 | AE12: 0.01834178 | AF12: 0.0185324 | AG12: 0.018718518 | AH12: 0.018900207 | AI12: 0.019077599 | AJ12: 0.019250764
A13: rural | B13: biomass | C13: BAU-S | D13: M hh | E13: 7.5819239 | F13: 7.6616629 | G13: 7.7405328 | H13: 7.8194662 | I13: 7.8982261 | J13: 7.9764658 | K13: 8.0538879 | L13: 8.1295497 | M13: 8.2041369 | N13: 8.2774649 | O13: 8.3493399 | P13: 8.4195569 | Q13: 8.4878512 | R13: 8.5541407 | S13: 8.618082 | T13: 8.6792766 | U13: 8.7374187 | V13: 8.7929594 | W13: 8.8452505 | X13: 8.894238 | Y13: 8.9399056 | Z13: 8.9822373 | AA13: 9.0225482 | AB13: 9.0594647 | AC13: 9.0929892 | AD13: 9.1231362 | AE13: 9.1499305 | AF13: 9.1754454 | AG13: 9.1976561 | AH13: 9.2166325 | AI13: 9.23247 | AJ13: 9.2452339
A14: rural | B14: charcoal | C14: BAU-S | D14: M hh | E14: 3.4552612 | F14: 3.4922136 | G14: 3.5287951 | H14: 3.5654276 | I14: 3.602 | J14: 3.638352 | K14: 3.6743459 | L14: 3.7095497 | M14: 3.7442746 | N14: 3.778435 | O14: 3.8119411 | P14: 3.8446982 | Q14: 3.8765843 | R14: 3.9075609 | S14: 3.9374701 | T14: 3.9661289 | U14: 3.9933963 | V14: 4.0194778 | W14: 4.044076 | X14: 4.0671653 | Y14: 4.0887372 | Z14: 4.1087837 | AA14: 4.1279055 | AB14: 4.1454735 | AC14: 4.1614881 | AD14: 4.1759551 | AE14: 4.1888851 | AF14: 4.2012266 | AG14: 4.2120523 | AH14: 4.2213934 | AI14: 4.2292929 | AJ14: 4.2357803
A15: rural | B15: Imp_biomass | C15: BAU-S | D15: M hh
A16: rural | B16: Imp_charcoal | C16: BAU-S | D16: M hh
A17: rural | B17: Gas | C17: BAU-S | D17: M hh | E17: 0.491435 | F17: 0.50711395 | G17: 0.52257824 | H17: 0.53790653 | I17: 0.55309814 | J17: 0.56814157 | K17: 0.58302564 | L17: 0.59768916 | M17: 0.61218723 | N17: 0.62651129 | O17: 0.64065059 | P17: 0.65459211 | Q17: 0.66212892 | R17: 0.66949217 | S17: 0.67665492 | T17: 0.68358548 | U17: 0.69025906 | V17: 0.69671052 | W17: 0.70288778 | X17: 0.70878547 | Y17: 0.71440122 | Z17: 0.71973264 | AA17: 0.72488429 | AB17: 0.72974525 | AC17: 0.73431457 | AD17: 0.73859228 | AE17: 0.7425793 | AF17: 0.74644317 | AG17: 0.75001892 | AH17: 0.75331118 | AI17: 0.75632676 | AJ17: 0.75907006
A18: rural | B18: kerosene | C18: BAU-S | D18: M hh | E18: 0.082702118 | F18: 0.079671246 | G18: 0.076689652 | H18: 0.073760752 | I18: 0.070876506 | J18: 0.068029071 | K18: 0.065212187 | L18: 0.062415614 | M18: 0.059642871 | N18: 0.056890677 | O18: 0.054156251 | P18: 0.05143726 | Q18: 0.048731514 | R18: 0.046038336 | S18: 0.043355965 | T18: 0.040682953 | U18: 0.038018857 | V18: 0.035366726 | W18: 0.032724978 | X18: 0.0300949 | Y18: 0.027477962 | Z18: 0.024875659 | AA18: 0.022292787 | AB18: 0.019726741 | AC18: 0.017179129 | AD18: 0.014651566 | AE18: 0.012145652 | AF18: 0.0096651018 | AG18: 0.0072081716 | AH18: 0.0047763904 | AI18: 0.0023712066 | AJ18: -6.042537e-06
A19: rural | B19: electric | C19: BAU-S | D19: M hh | E19: 0.00218105 | F19: 0.0022147546 | G19: 0.0022480469 | H19: 0.002281214 | I19: 0.0023142028 | J19: 0.0023469246 | K19: 0.0023793023 | L19: 0.0024110645 | M19: 0.0024424195 | N19: 0.0024733177 | O19: 0.002503705 | P19: 0.0025335229 | Q19: 0.0025626933 | R19: 0.0025911919 | S19: 0.0026189145 | T19: 0.0026457384 | U19: 0.0026715677 | V19: 0.0026965373 | W19: 0.0027204457 | X19: 0.002743272 | Y19: 0.0027650071 | Z19: 0.0027856418 | AA19: 0.0028055807 | AB19: 0.0028243944 | AC19: 0.0028420795 | AD19: 0.0028586359 | AE19: 0.0028740671 | AF19: 0.0028890218 | AG19: 0.0029028613 | AH19: 0.0029156036 | AI19: 0.0029272751 | AJ19: 0.0029378927
A20: rural | B20: pellets | C20: BAU-S | D20: M hh
A21: rural | B21: ethanol | C21: BAU-S | D21: M hh
A22: rural | B22: biogas | C22: BAU-S | D22: M hh
A23: rural | B23: other | C23: BAU-S | D23: M hh | E23: 0.010594668 | F23: 0.010758392 | G23: 0.010920113 | H23: 0.011081225 | I23: 0.011241471 | J23: 0.011400421 | K23: 0.011557699 | L23: 0.011711987 | M23: 0.011864297 | N23: 0.012014388 | O23: 0.012161997 | P23: 0.012306841 | Q23: 0.012448539 | R23: 0.012586974 | S23: 0.012721639 | T23: 0.012851939 | U23: 0.012977407 | V23: 0.0130987 | W23: 0.013214837 | X23: 0.013325718 | Y23: 0.013431299 | Z23: 0.013531534 | AA23: 0.013628389 | AB23: 0.013719778 | AC23: 0.013805685 | AD23: 0.01388611 | AE23: 0.013961068 | AF23: 0.014033712 | AG23: 0.014100939 | AH23: 0.014162836 | AI23: 0.014219531 | AJ23: 0.014271108
A24: urban | B24: biomass | C24: BAU-S | D24: M hh | E24: 1.058853 | F24: 1.09877 | G24: 1.1403067 | H24: 1.1829269 | I24: 1.2266187 | J24: 1.2713498 | K24: 1.317091 | L24: 1.3641407 | M24: 1.4122031 | N24: 1.46126 | O24: 1.5112887 | P24: 1.5622614 | Q24: 1.6142089 | R24: 1.6670493 | S24: 1.7207173 | T24: 1.7751296 | U24: 1.8302145 | V24: 1.8856935 | W24: 1.941764 | X24: 1.9983974 | Y24: 2.0555715 | Z24: 2.1132639 | AA24: 2.1709224 | AB24: 2.2290216 | AC24: 2.2875393 | AD24: 2.346456 | AE24: 2.4057544 | AF24: 2.4646085 | AG24: 2.5237767 | AH24: 2.583253 | AI24: 2.6430396 | AJ24: 2.7031312
A25: urban | B25: charcoal | C25: BAU-S | D25: M hh | E25: 1.9486116 | F25: 2.0224262 | G25: 2.0992561 | H25: 2.1781138 | I25: 2.2589773 | J25: 2.3417871 | K25: 2.4264892 | L25: 2.5136338 | M25: 2.6026759 | N25: 2.6935823 | O25: 2.7863113 | P25: 2.8808117 | Q25: 2.9771407 | R25: 3.0751476 | S25: 3.1747119 | T25: 3.2756802 | U25: 3.3779203 | V25: 3.4809181 | W25: 3.5850381 | X25: 3.6902269 | Y25: 3.7964441 | Z25: 3.9036478 | AA25: 4.0108183 | AB25: 4.1188315 | AC25: 4.2276468 | AD25: 4.3372278 | AE25: 4.4475423 | AF25: 4.5570632 | AG25: 4.6671919 | AH25: 4.7779174 | AI25: 4.8892436 | AJ25: 5.0011605
A26: urban | B26: Imp_biomass | C26: BAU-S | D26: M hh
A27: urban | B27: Imp_charcoal | C27: BAU-S | D27: M hh
A28: urban | B28: Gas | C28: BAU-S | D28: M hh | E28: 1.6362229 | F28: 1.7061999 | G28: 1.7790035 | H28: 1.8538194 | I28: 1.9306431 | J28: 2.0094364 | K28: 2.0901641 | L28: 2.173312 | M28: 2.258422 | N28: 2.345474 | O28: 2.4344399 | P28: 2.525282 | Q28: 2.6180576 | R28: 2.7126403 | S28: 2.8089292 | T28: 2.9067924 | U28: 3.0061151 | V28: 3.1064406 | W28: 3.2080931 | X28: 3.3110258 | Y28: 3.4152028 | Z28: 3.5205868 | AA28: 3.6262558 | AB28: 3.7329972 | AC28: 3.8407734 | AD28: 3.9495506 | AE28: 4.0592984 | AF28: 4.1686189 | AG28: 4.2787867 | AH28: 4.3897899 | AI28: 4.5016309 | AJ28: 4.6142991
A29: urban | B29: kerosene | C29: BAU-S | D29: M hh | E29: 0.71589021 | F29: 0.70820482 | G29: 0.70026293 | H29: 0.6916393 | I29: 0.68226931 | J29: 0.67208255 | K29: 0.66101679 | L29: 0.64917149 | M29: 0.6363504 | N29: 0.62250778 | O29: 0.60759953 | P29: 0.59158319 | Q29: 0.57444098 | R29: 0.55611576 | S29: 0.5365637 | T29: 0.51574204 | U29: 0.4936185 | V29: 0.47011533 | W29: 0.44528618 | X29: 0.41912111 | Y29: 0.39161356 | Z29: 0.36275828 | AA29: 0.33247041 | AB29: 0.30084348 | AC29: 0.2678777 | AD29: 0.23357472 | AE29: 0.19793739 | AF29: 0.16091657 | AG29: 0.1225949 | AH29: 0.082978967 | AI29: 0.042075442 | AJ29: -0.00010950705
A30: urban | B30: pellets | C30: BAU-S | D30: M hh
A31: urban | B31: ethanol | C31: BAU-S | D31: M hh
A32: urban | B32: biogas | C32: BAU-S | D32: M hh
A33: urban | B33: electric | C33: BAU-S | D33: M hh | E33: 0.03446059 | F33: 0.035934381 | G33: 0.037467701 | H33: 0.039043403 | I33: 0.040661392 | J33: 0.042320863 | K33: 0.044021074 | L33: 0.045772256 | M33: 0.047564763 | N33: 0.049398172 | O33: 0.051271886 | P33: 0.053185118 | Q33: 0.05513907 | R33: 0.057131083 | S33: 0.059159029 | T33: 0.061220131 | U33: 0.063311973 | V33: 0.065424934 | W33: 0.067565844 | X33: 0.069733715 | Y33: 0.071927795 | Z33: 0.074147293 | AA33: 0.076372795 | AB33: 0.078620882 | AC33: 0.080890763 | AD33: 0.083181727 | AE33: 0.085493132 | AF33: 0.087795537 | AG33: 0.090115786 | AH33: 0.092453633 | AI33: 0.094809122 | AJ33: 0.097182033
A34: urban | B34: other | C34: BAU-S | D34: M hh | E34: 0.0017657781 | F34: 0.0018412959 | G34: 0.001919864 | H34: 0.0020006037 | I34: 0.0020835103 | J34: 0.0021685424 | K34: 0.0022556621 | L34: 0.0023453936 | M34: 0.0024372426 | N34: 0.0025311873 | O34: 0.0026271974 | P34: 0.0027252324 | Q34: 0.0028253539 | R34: 0.0029274256 | S34: 0.0030313386 | T34: 0.0031369505 | U34: 0.0032441375 | V34: 0.0033524068 | W34: 0.003462108 | X34: 0.0035731909 | Y34: 0.0036856166 | Z34: 0.0037993448 | AA34: 0.0039133807 | AB34: 0.0040285738 | AC34: 0.0041448837 | AD34: 0.0042622738 | AE34: 0.0043807114 | AF34: 0.0044986878 | AG34: 0.0046175785 | AH34: 0.004737371 | AI34: 0.0048580674 | AJ34: 0.0049796566
A37: population | B37: Fuel | C37: Scenario | D37: unit | E37: 2019 | F37: 2020 | G37: 2021 | H37: 2022 | I37: 2023 | J37: 2024 | K37: 2025 | L37: 2026 | M37: 2027 | N37: 2028 | O37: 2029 | P37: 2030 | Q37: 2031 | R37: 2032 | S37: 2033 | T37: 2034 | U37: 2035 | V37: 2036 | W37: 2037 | X37: 2038 | Y37: 2039 | Z37: 2040 | AA37: 2041 | AB37: 2042 | AC37: 2043 | AD37: 2044 | AE37: 2045 | AF37: 2046 | AG37: 2047 | AH37: 2048 | AI37: 2049 | AJ37: 2050
A38: overall | B38: biomass | C38: BAU-S | D38: M hh | E38: =70.745553370709%-E40 -> #REF! | F38: =E38+($P38-$E38)/($P$37-$E$37) -> #REF! | G38: =F38+($P38-$E38)/($P$37-$E$37) -> #REF! | H38: =G38+($P38-$E38)/($P$37-$E$37) -> #REF! | I38: =H38+($P38-$E38)/($P$37-$E$37) -> #REF! | J38: =I38+($P38-$E38)/($P$37-$E$37) -> #REF! | K38: =J38+($P38-$E38)/($P$37-$E$37) -> #REF! | L38: =K38+($P38-$E38)/($P$37-$E$37) -> #REF! | M38: =L38+($P38-$E38)/($P$37-$E$37) -> #REF! | ... O38: =N38+($P38-$E38)/($P$37-$E$37) -> #REF! | P38: =0.39*0.63 -> 0.2457 | Q38: =P38+($AJ38-$P38)/($AJ$37-$P$37) -> 0.236065 | R38: =Q38+($AJ38-$P38)/($AJ$37-$P$37) -> 0.22643 | S38: =R38+($AJ38-$P38)/($AJ$37-$P$37) -> 0.216795 | T38: =S38+($AJ38-$P38)/($AJ$37-$P$37) -> 0.20716 | U38: =T38+($AJ38-$P38)/($AJ$37-$P$37) -> 0.197525 | V38: =U38+($AJ38-$P38)/($AJ$37-$P$37) -> 0.18789 | W38: =V38+($AJ38-$P38)/($AJ$37-$P$37) -> 0.178255 | X38: =W38+($AJ38-$P38)/($AJ$37-$P$37) -> 0.16862 | ... AI38: =AH38+($AJ38-$P38)/($AJ$37-$P$37) -> 0.062635 | AJ38: =0.1*0.53 -> 0.053
A39: overall | B39: charcoal | C39: BAU-S | D39: M hh | E39: =44.2437039080182%-E41 -> #REF! | F39: =E39+($P39-$E39)/($P$37-$E$37) -> #REF! | G39: =F39+($P39-$E39)/($P$37-$E$37) -> #REF! | H39: =G39+($P39-$E39)/($P$37-$E$37) -> #REF! | I39: =H39+($P39-$E39)/($P$37-$E$37) -> #REF! | J39: =I39+($P39-$E39)/($P$37-$E$37) -> #REF! | K39: =J39+($P39-$E39)/($P$37-$E$37) -> #REF! | L39: =K39+($P39-$E39)/($P$37-$E$37) -> #REF! | M39: =L39+($P39-$E39)/($P$37-$E$37) -> #REF! | ... O39: =N39+($P39-$E39)/($P$37-$E$37) -> #REF! | P39: =0.39*0.43 -> 0.1677 | Q39: =P39+($AJ39-$P39)/($AJ$37-$P$37) -> 0.161365 | R39: =Q39+($AJ39-$P39)/($AJ$37-$P$37) -> 0.15503 | S39: =R39+($AJ39-$P39)/($AJ$37-$P$37) -> 0.148695 | T39: =S39+($AJ39-$P39)/($AJ$37-$P$37) -> 0.14236 | U39: =T39+($AJ39-$P39)/($AJ$37-$P$37) -> 0.136025 | V39: =U39+($AJ39-$P39)/($AJ$37-$P$37) -> 0.12969 | W39: =V39+($AJ39-$P39)/($AJ$37-$P$37) -> 0.123355 | X39: =W39+($AJ39-$P39)/($AJ$37-$P$37) -> 0.11702 | ... AI39: =AH39+($AJ39-$P39)/($AJ$37-$P$37) -> 0.047335 | AJ39: =0.1*0.41 -> 0.041
A40: overall | B40: Imp_biomass | C40: BAU-S | D40: M hh | E40: {=SUM(params!#REF!/100)} -> #REF! | F40: =E40+($P40-$E40)/($P$37-$E$37) -> #REF! | G40: =F40+($P40-$E40)/($P$37-$E$37) -> #REF! | H40: =G40+($P40-$E40)/($P$37-$E$37) -> #REF! | I40: =H40+($P40-$E40)/($P$37-$E$37) -> #REF! | J40: =I40+($P40-$E40)/($P$37-$E$37) -> #REF! | K40: =J40+($P40-$E40)/($P$37-$E$37) -> #REF! | L40: =K40+($P40-$E40)/($P$37-$E$37) -> #REF! | M40: =L40+($P40-$E40)/($P$37-$E$37) -> #REF! | ... O40: =N40+($P40-$E40)/($P$37-$E$37) -> #REF! | P40: =0.61*0.63 -> 0.3843 | Q40: =P40+($AJ40-$P40)/($AJ$37-$P$37) -> 0.388935 | R40: =Q40+($AJ40-$P40)/($AJ$37-$P$37) -> 0.39357 | S40: =R40+($AJ40-$P40)/($AJ$37-$P$37) -> 0.398205 | T40: =S40+($AJ40-$P40)/($AJ$37-$P$37) -> 0.40284 | U40: =T40+($AJ40-$P40)/($AJ$37-$P$37) -> 0.407475 | V40: =U40+($AJ40-$P40)/($AJ$37-$P$37) -> 0.41211 | W40: =V40+($AJ40-$P40)/($AJ$37-$P$37) -> 0.416745 | X40: =W40+($AJ40-$P40)/($AJ$37-$P$37) -> 0.42138 | ... AI40: =AH40+($AJ40-$P40)/($AJ$37-$P$37) -> 0.472365 | AJ40: =0.9*0.53 -> 0.477 | AK40: 2019 is based on MoE study; 2030 and 2050 are from KNCTS targets
A41: overall | B41: Imp_charcoal | C41: BAU-S | D41: M hh | E41: =params!#REF!/100 -> #REF! | F41: =E41+($P41-$E41)/($P$37-$E$37) -> #REF! | G41: =F41+($P41-$E41)/($P$37-$E$37) -> #REF! | H41: =G41+($P41-$E41)/($P$37-$E$37) -> #REF! | I41: =H41+($P41-$E41)/($P$37-$E$37) -> #REF! | J41: =I41+($P41-$E41)/($P$37-$E$37) -> #REF! | K41: =J41+($P41-$E41)/($P$37-$E$37) -> #REF! | L41: =K41+($P41-$E41)/($P$37-$E$37) -> #REF! | M41: =L41+($P41-$E41)/($P$37-$E$37) -> #REF! | ... O41: =N41+($P41-$E41)/($P$37-$E$37) -> #REF! | P41: =0.61*0.43 -> 0.2623 | Q41: =P41+($AJ41-$P41)/($AJ$37-$P$37) -> 0.267635 | R41: =Q41+($AJ41-$P41)/($AJ$37-$P$37) -> 0.27297 | S41: =R41+($AJ41-$P41)/($AJ$37-$P$37) -> 0.278305 | T41: =S41+($AJ41-$P41)/($AJ$37-$P$37) -> 0.28364 | U41: =T41+($AJ41-$P41)/($AJ$37-$P$37) -> 0.288975 | V41: =U41+($AJ41-$P41)/($AJ$37-$P$37) -> 0.29431 | W41: =V41+($AJ41-$P41)/($AJ$37-$P$37) -> 0.299645 | X41: =W41+($AJ41-$P41)/($AJ$37-$P$37) -> 0.30498 | ... AI41: =AH41+($AJ41-$P41)/($AJ$37-$P$37) -> 0.363665 | AJ41: =0.9*0.41 -> 0.369 | AK41: Fill in blanks with 61% f biomass usedin 2030 and 90% of biomass users in 2050
A42: overall | B42: Gas | C42: BAU-S | D42: M hh | E42: 0.1742 | F42: =E42+($P42-$E42)/($P$37-$E$37) -> 0.17674743 | G42: =F42+($P42-$E42)/($P$37-$E$37) -> 0.17929486 | H42: =G42+($P42-$E42)/($P$37-$E$37) -> 0.18184229 | I42: =H42+($P42-$E42)/($P$37-$E$37) -> 0.18438972 | J42: =I42+($P42-$E42)/($P$37-$E$37) -> 0.18693715 | K42: =J42+($P42-$E42)/($P$37-$E$37) -> 0.18948458 | L42: =K42+($P42-$E42)/($P$37-$E$37) -> 0.19203201 | M42: =L42+($P42-$E42)/($P$37-$E$37) -> 0.19457944 | ... O42: =N42+($P42-$E42)/($P$37-$E$37) -> 0.1996743 | P42: 0.20222173 | Q42: =P42+($AJ42-$P42)/($AJ$37-$P$37) -> 0.20411393 | R42: =Q42+($AJ42-$P42)/($AJ$37-$P$37) -> 0.20600612 | S42: =R42+($AJ42-$P42)/($AJ$37-$P$37) -> 0.20789832 | T42: =S42+($AJ42-$P42)/($AJ$37-$P$37) -> 0.20979051 | U42: =T42+($AJ42-$P42)/($AJ$37-$P$37) -> 0.21168271 | V42: =U42+($AJ42-$P42)/($AJ$37-$P$37) -> 0.2135749 | W42: =V42+($AJ42-$P42)/($AJ$37-$P$37) -> 0.21546709 | X42: =W42+($AJ42-$P42)/($AJ$37-$P$37) -> 0.21735929 | ... AI42: =AH42+($AJ42-$P42)/($AJ$37-$P$37) -> 0.23817343 | AJ42: 0.24006562
...

Sheet BAU_Scenario
B1: Fuel | C1: Scenario | D1: unit | E1: 2010 | F1: 2011 | G1: 2012 | H1: 2013 | I1: 2014 | J1: 2015 | K1: 2016 | L1: 2017 | M1: 2018 | N1: 2019 | O1: 2020 | P1: 2021 | Q1: 2022 | R1: 2023 | S1: 2024 | T1: 2025 | U1: 2026 | V1: 2027 | W1: 2028 | X1: 2029 | Y1: 2030 | Z1: 2031 | AA1: 2032 | AB1: 2033 | AC1: 2034 | AD1: 2035 | AE1: 2036 | AF1: 2037 | AG1: 2038 | AH1: 2039 | AI1: 2040 | AJ1: 2041 | AK1: 2042 | AL1: 2043 | AM1: 2044 | AN1: 2045 | AO1: 2046 | AP1: 2047 | AQ1: 2048 | AR1: 2049 | AS1: 2050 | AT1: New users 2025-2030 | AU1: New users 2030-2040 | AV1: Assumptions 2050
A2: overall | B2: fuelwood | C2: BAU | D2: M ppl | E2: =SUM(E13,E24) -> 14.596192 | F2: =SUM(F13,F24) -> 14.838968 | G2: =SUM(G13,G24) -> 15.07484 | H2: =SUM(H13,H24) -> 15.30407 | I2: =SUM(I13,I24) -> 15.527444 | J2: =SUM(J13,J24) -> 15.745237 | K2: =SUM(K13,K24) -> 15.95671 | L2: =SUM(L13,L24) -> 16.160459 | ... AS2: =SUM(AS13,AS24) -> 7.4830211 | AT2: =Y2-T2 -> -0.56478054 | AU2: =AI2-Y2 -> -3.1798019
A3: overall | B3: charcoal | C3: BAU | D3: M ppl | E3: =SUM(E14,E25) -> 3.9194128 | F3: =SUM(F14,F25) -> 4.363263 | G3: =SUM(G14,G25) -> 4.8321665 | H3: =SUM(H14,H25) -> 5.3272586 | I3: =SUM(I14,I25) -> 5.8499012 | J3: =SUM(J14,J25) -> 6.401436 | K3: =SUM(K14,K25) -> 6.9829929 | L3: =SUM(L14,L25) -> 7.5954556 | ... AS3: =SUM(AS14,AS25) -> 49.181114 | AT3: =Y3-T3 -> 5.3580963 | AU3: =AI3-Y3 -> 13.329524
A4: overall | B4: Imp_fuelwood | C4: BAU | D4: M ppl | E4: =SUM(E15,E26) -> 0 | F4: =SUM(F15,F26) -> 0 | G4: =SUM(G15,G26) -> 0 | H4: =SUM(H15,H26) -> 0 | I4: =SUM(I15,I26) -> 0.006577908 | J4: =SUM(J15,J26) -> 0.021719287 | K4: =SUM(K15,K26) -> 0.03825534 | L4: =SUM(L15,L26) -> 0.056266175 | ... AS4: =SUM(AS15,AS26) -> 1.8694645 | AT4: =Y4-T4 -> 0.18690915 | AU4: =AI4-Y4 -> 0.5577006
A5: overall | B5: Imp_charcoal | C5: BAU | D5: M ppl | E5: =SUM(E16,E27) -> 0 | F5: =SUM(F16,F27) -> 0 | G5: =SUM(G16,G27) -> 0 | H5: =SUM(H16,H27) -> 0 | I5: =SUM(I16,I27) -> 0.002192636 | J5: =SUM(J16,J27) -> 0.0072397622 | K5: =SUM(K16,K27) -> 0.01275178 | L5: =SUM(L16,L27) -> 0.018755392 | ... AS5: =SUM(AS16,AS27) -> 0.62315482 | AT5: =Y5-T5 -> 0.062303051 | AU5: =AI5-Y5 -> 0.1859002
A6: overall | B6: Gas | C6: BAU | D6: M ppl | E6: =SUM(E17,E28) -> 0.0025315047 | F6: =SUM(F17,F28) -> 0.0025333978 | G6: =SUM(G17,G28) -> 0.0053706729 | H6: =SUM(H17,H28) -> 0.009137324 | I6: =SUM(I17,I28) -> 0.013249949 | J6: =SUM(J17,J28) -> 0.017729443 | K6: =SUM(K17,K28) -> 0.022597302 | L6: =SUM(L17,L28) -> 0.027875004 | ... AS6: =SUM(AS17,AS28) -> 0 | AT6: =Y6-T6 -> -0.002076067 | AU6: =AI6-Y6 -> -0.022225021
A7: overall | B7: kerosene | C7: BAU | D7: M ppl | E7: =SUM(E18,E29) -> 0.0080280817 | F7: =SUM(F18,F29) -> 0.0078028154 | G7: =SUM(G18,G29) -> 0.0075326574 | H7: =SUM(H18,H29) -> 0.0072151578 | I7: =SUM(I18,I29) -> 0.0068477708 | J7: =SUM(J18,J29) -> 0.0064274962 | K7: =SUM(K18,K29) -> 0.0059508307 | L7: =SUM(L18,L29) -> 0.0054139275 | ... AS7: =SUM(AS18,AS29) -> 0 | AT7: =Y7-T7 -> 0 | AU7: =AI7-Y7 -> 0
A8: overall | B8: electric | C8: BAU | D8: M ppl | E8: =SUM(E19,E30) -> 0.84443093 | F8: =SUM(F19,F30) -> 0.85423194 | G8: =SUM(G19,G30) -> 0.86268906 | H8: =SUM(H19,H30) -> 0.86974335 | I8: =SUM(I19,I30) -> 0.87534636 | J8: =SUM(J19,J30) -> 0.87941721 | K8: =SUM(K19,K30) -> 0.88182789 | L8: =SUM(L19,L30) -> 0.88241414 | ... AS8: =SUM(AS19,AS30) -> 0 | AT8: =Y8-T8 -> -0.022724774 | AU8: =AI8-Y8 -> -0.2342907
A9: overall | B9: pellets | C9: BAU | D9: M ppl | E9: =SUM(E20,E31) -> 0 | F9: =SUM(F20,F31) -> 0 | G9: =SUM(G20,G31) -> 0 | H9: =SUM(H20,H31) -> 0 | I9: =SUM(I20,I31) -> 0 | J9: =SUM(J20,J31) -> 0 | K9: =SUM(K20,K31) -> 0 | L9: =SUM(L20,L31) -> 0 | ... AS9: =SUM(AS20,AS31) -> 0 | AT9: =Y9-T9 -> 0 | AU9: =AI9-Y9 -> 0
A10: overall | B10: ethanol | C10: BAU | D10: M ppl | E10: =SUM(E21,E32) -> 0 | F10: =SUM(F21,F32) -> 0 | G10: =SUM(G21,G32) -> 0 | H10: =SUM(H21,H32) -> 0 | I10: =SUM(I21,I32) -> 0 | J10: =SUM(J21,J32) -> 0 | K10: =SUM(K21,K32) -> 0 | L10: =SUM(L21,L32) -> 0 | ... AS10: =SUM(AS21,AS32) -> 0 | AT10: =Y10-T10 -> 0 | AU10: =AI10-Y10 -> 0
A11: overall | B11: biogas | C11: BAU | D11: M ppl | E11: =SUM(E22,E33) -> 0 | F11: =SUM(F22,F33) -> 0 | G11: =SUM(G22,G33) -> 0 | H11: =SUM(H22,H33) -> 0 | I11: =SUM(I22,I33) -> 0 | J11: =SUM(J22,J33) -> 0 | K11: =SUM(K22,K33) -> 0 | L11: =SUM(L22,L33) -> 0 | ... AS11: =SUM(AS22,AS33) -> 0 | AT11: =Y11-T11 -> 0 | AU11: =AI11-Y11 -> 0
A12: overall | B12: other | C12: BAU | D12: M ppl | E12: =SUM(E23,E34) -> 0.1502645 | F12: =SUM(F23,F34) -> 0.15025494 | G12: =SUM(G23,G34) -> 0.14999647 | H12: =SUM(H23,H34) -> 0.149485 | I12: =SUM(I23,I34) -> 0.14872083 | J12: =SUM(J23,J34) -> 0.14769826 | K12: =SUM(K23,K34) -> 0.14640136 | L12: =SUM(L23,L34) -> 0.14480796 | ... AS12: =SUM(AS23,AS34) -> 0 | AT12: =Y12-T12 -> -0.013308914 | AU12: =AI12-Y12 -> -0.044249216
A13: rural | B13: fuelwood | C13: BAU | D13: M ppl | E13: =E49*E$72 -> 12.481837 | F13: =F49*F$72 -> 12.688089 | G13: =G49*G$72 -> 12.890034 | H13: =H49*H$72 -> 13.088057 | I13: =I49*I$72 -> 13.283039 | J13: =J49*J$72 -> 13.475428 | K13: =K49*K$72 -> 13.664774 | L13: =L49*L$72 -> 13.850053 | ... AS13: =AS49*AS$72 -> 7.4830211 | AT13: =Y13-T13 -> -0.5090847 | AU13: =AI13-Y13 -> -2.5296646
A14: rural | B14: charcoal | C14: BAU | D14: M ppl | E14: =E50*E$72 -> 0.10024641 | F14: =F50*F$72 -> 0.2644062 | G14: =G50*G$72 -> 0.43774169 | H14: =H50*H$72 -> 0.6204436 | I14: =I50*I$72 -> 0.81276291 | J14: =J50*J$72 -> 1.0149777 | K14: =K50*K$72 -> 1.227324 | L14: =L50*L$72 -> 1.4499654 | ... AS14: =AS50*AS$72 -> 20.578308 | AT14: =Y14-T14 -> 2.6430805 | AU14: =AI14-Y14 -> 6.4857206
A15: rural | B15: Imp_fuelwood | C15: BAU | D15: M ppl | E15: =E51*E$72 -> 0 | F15: =F51*F$72 -> 0 | G15: =G51*G$72 -> 0 | H15: =H51*H$72 -> 0 | I15: =I51*I$72 -> 0 | J15: =J51*J$72 -> 0 | K15: =K51*K$72 -> 0 | L15: =L51*L$72 -> 0 | ... AS15: =AS51*AS$72 -> 0 | AT15: =Y15-T15 -> 0 | AU15: =AI15-Y15 -> 0
A16: rural | B16: Imp_charcoal | C16: BAU | D16: M ppl | E16: =E52*E$72 -> 0 | F16: =F52*F$72 -> 0 | G16: =G52*G$72 -> 0 | H16: =H52*H$72 -> 0 | I16: =I52*I$72 -> 0 | J16: =J52*J$72 -> 0 | K16: =K52*K$72 -> 0 | L16: =L52*L$72 -> 0 | ... AS16: =AS52*AS$72 -> 0 | AT16: =Y16-T16 -> 0 | AU16: =AI16-Y16 -> 0
A17: rural | B17: Gas | C17: BAU | D17: M ppl | E17: =E53*E$72 -> 0.0025315047 | F17: =F53*F$72 -> 0.0025333978 | G17: =G53*G$72 -> 0.002532154 | H17: =H53*H$72 -> 0.002527805 | I17: =I53*I$72 -> 0.0025204698 | J17: =J53*J$72 -> 0.0025101714 | K17: =K53*K$72 -> 0.0024967599 | L17: =L53*L$72 -> 0.0024799853 | ... AS17: =AS53*AS$72 -> 0 | AT17: =Y17-T17 -> -0.00024063775 | AU17: =AI17-Y17 -> -0.00080006767
A18: rural | B18: kerosene | C18: BAU | D18: M ppl | E18: =E54*E$72 -> 0 | F18: =F54*F$72 -> 0 | G18: =G54*G$72 -> 0 | H18: =H54*H$72 -> 0 | I18: =I54*I$72 -> 0 | J18: =J54*J$72 -> 0 | K18: =K54*K$72 -> 0 | L18: =L54*L$72 -> 0 | ... AS18: =AS54*AS$72 -> 0 | AT18: =Y18-T18 -> 0 | AU18: =AI18-Y18 -> 0
A19: rural | B19: electric | C19: BAU | D19: M ppl | E19: =E55*E$72 -> 0.066425614 | F19: =F55*F$72 -> 0.065230877 | G19: =G55*G$72 -> 0.063883296 | H19: =H55*H$72 -> 0.062382272 | I19: =I55*I$72 -> 0.060729054 | J19: =J55*J$72 -> 0.058922149 | K19: =K55*K$72 -> 0.056955784 | L19: =L55*L$72 -> 0.054822085 | ... AS19: =AS55*AS$72 -> 0 | AT19: =Y19-T19 -> -0.0037104262 | AU19: =AI19-Y19 -> -0.012336353
A20: rural | B20: pellets | C20: BAU | D20: M ppl | E20: =E56*E$72 -> 0 | F20: =F56*F$72 -> 0 | G20: =G56*G$72 -> 0 | H20: =H56*H$72 -> 0 | I20: =I56*I$72 -> 0 | J20: =J56*J$72 -> 0 | K20: =K56*K$72 -> 0 | L20: =L56*L$72 -> 0 | ... AS20: =AS56*AS$72 -> 0 | AT20: =Y20-T20 -> 0 | AU20: =AI20-Y20 -> 0
A21: rural | B21: ethanol | C21: BAU | D21: M ppl | E21: =E57*E$72 -> 0 | F21: =F57*F$72 -> 0 | G21: =G57*G$72 -> 0 | H21: =H57*H$72 -> 0 | I21: =I57*I$72 -> 0 | J21: =J57*J$72 -> 0 | K21: =K57*K$72 -> 0 | L21: =L57*L$72 -> 0 | ... AS21: =AS57*AS$72 -> 0 | AT21: =Y21-T21 -> 0 | AU21: =AI21-Y21 -> 0
A22: rural | B22: biogas | C22: BAU | D22: M ppl | E22: =E58*E$72 -> 0 | F22: =F58*F$72 -> 0 | G22: =G58*G$72 -> 0 | H22: =H58*H$72 -> 0 | I22: =I58*I$72 -> 0 | J22: =J58*J$72 -> 0 | K22: =K58*K$72 -> 0 | L22: =L58*L$72 -> 0 | ... AS22: =AS58*AS$72 -> 0 | AT22: =Y22-T22 -> 0 | AU22: =AI22-Y22 -> 0
A23: rural | B23: other | C23: BAU | D23: M ppl | E23: =E59*E$72 -> 0.12971608 | F23: =F59*F$72 -> 0.13028071 | G23: =G59*G$72 -> 0.13071111 | H23: =H59*H$72 -> 0.13100944 | I23: =I59*I$72 -> 0.1311825 | J23: =J59*J$72 -> 0.13123227 | K23: =K59*K$72 -> 0.13115174 | L23: =L59*L$72 -> 0.1309286 | ... AS23: =AS59*AS$72 -> 0 | AT23: =Y23-T23 -> -0.013308914 | AU23: =AI23-Y23 -> -0.044249216
A24: urban | B24: fuelwood | C24: BAU | D24: M ppl | E24: =E60*E$73 -> 2.1143551 | F24: =F60*F$73 -> 2.1508796 | G24: =G60*G$73 -> 2.1848065 | H24: =H60*H$73 -> 2.2160134 | I24: =I60*I$73 -> 2.2444052 | J24: =J60*J$73 -> 2.2698088 | K24: =K60*K$73 -> 2.2919362 | L24: =L60*L$73 -> 2.3104059 | ... AS24: =AS60*AS$73 -> 0 | AT24: =Y24-T24 -> -0.055695846 | AU24: =AI24-Y24 -> -0.65013724
A25: urban | B25: charcoal | C25: BAU | D25: M ppl | E25: =E61*E$73 -> 3.8191664 | F25: =F61*F$73 -> 4.0988568 | G25: =G61*G$73 -> 4.3944248 | H25: =H61*H$73 -> 4.706815 | I25: =I61*I$73 -> 5.0371383 | J25: =J61*J$73 -> 5.3864583 | K25: =K61*K$73 -> 5.7556689 | L25: =L61*L$73 -> 6.1454902 | ... AS25: =AS61*AS$73 -> 28.602806 | AT25: =Y25-T25 -> 2.7150158 | AU25: =AI25-Y25 -> 6.8438035
A26: urban | B26: Imp_fuelwood | C26: BAU | D26: M ppl | E26: =E62*E$73 -> 0 | F26: =F62*F$73 -> 0 | G26: =G62*G$73 -> 0 | H26: =H62*H$73 -> 0 | I26: =I62*I$73 -> 0.006577908 | J26: =J62*J$73 -> 0.021719287 | K26: =K62*K$73 -> 0.03825534 | L26: =L62*L$73 -> 0.056266175 | ... AS26: =AS62*AS$73 -> 1.8694645 | AT26: =Y26-T26 -> 0.18690915 | AU26: =AI26-Y26 -> 0.5577006
A27: urban | B27: Imp_charcoal | C27: BAU | D27: M ppl | E27: =E63*E$73 -> 0 | F27: =F63*F$73 -> 0 | G27: =G63*G$73 -> 0 | H27: =H63*H$73 -> 0 | I27: =I63*I$73 -> 0.002192636 | J27: =J63*J$73 -> 0.0072397622 | K27: =K63*K$73 -> 0.01275178 | L27: =L63*L$73 -> 0.018755392 | ... AS27: =AS63*AS$73 -> 0.62315482 | AT27: =Y27-T27 -> 0.062303051 | AU27: =AI27-Y27 -> 0.1859002
A28: urban | B28: Gas | C28: BAU | D28: M ppl | E28: =E64*E$73 -> 0 | F28: =F64*F$73 -> 0 | G28: =G64*G$73 -> 0.0028385189 | H28: =H64*H$73 -> 0.006609519 | I28: =I64*I$73 -> 0.01072948 | J28: =J64*J$73 -> 0.015219271 | K28: =K64*K$73 -> 0.020100542 | L28: =L64*L$73 -> 0.025395019 | ... AS28: =AS64*AS$73 -> 0 | AT28: =Y28-T28 -> -0.0018354293 | AU28: =AI28-Y28 -> -0.021424953
A29: urban | B29: kerosene | C29: BAU | D29: M ppl | E29: =E65*E$73 -> 0.0080280817 | F29: =F65*F$73 -> 0.0078028154 | G29: =G65*G$73 -> 0.0075326574 | H29: =H65*H$73 -> 0.0072151578 | I29: =I65*I$73 -> 0.0068477708 | J29: =J65*J$73 -> 0.0064274962 | K29: =K65*K$73 -> 0.0059508307 | L29: =L65*L$73 -> 0.0054139275 | ... AS29: =AS65*AS$73 -> 0 | AT29: =Y29-T29 -> 0 | AU29: =AI29-Y29 -> 0
A30: urban | B30: electric | C30: BAU | D30: M ppl | E30: =E66*E$73 -> 0.77800532 | F30: =F66*F$73 -> 0.78900106 | G30: =G66*G$73 -> 0.79880577 | H30: =H66*H$73 -> 0.80736108 | I30: =I66*I$73 -> 0.8146173 | J30: =J66*J$73 -> 0.82049506 | K30: =K66*K$73 -> 0.82487211 | L30: =L66*L$73 -> 0.82759205 | ... AS30: =AS66*AS$73 -> 0 | AT30: =Y30-T30 -> -0.019014348 | AU30: =AI30-Y30 -> -0.22195435
A31: urban | B31: pellets | C31: BAU | D31: M ppl | E31: =E67*E$73 -> 0 | F31: =F67*F$73 -> 0 | G31: =G67*G$73 -> 0 | H31: =H67*H$73 -> 0 | I31: =I67*I$73 -> 0 | J31: =J67*J$73 -> 0 | K31: =K67*K$73 -> 0 | L31: =L67*L$73 -> 0 | ... AS31: =AS67*AS$73 -> 0 | AT31: =Y31-T31 -> 0 | AU31: =AI31-Y31 -> 0
A32: urban | B32: ethanol | C32: BAU | D32: M ppl | E32: =E68*E$73 -> 0 | F32: =F68*F$73 -> 0 | G32: =G68*G$73 -> 0 | H32: =H68*H$73 -> 0 | I32: =I68*I$73 -> 0 | J32: =J68*J$73 -> 0 | K32: =K68*K$73 -> 0 | L32: =L68*L$73 -> 0 | ... AS32: =AS68*AS$73 -> 0 | AT32: =Y32-T32 -> 0 | AU32: =AI32-Y32 -> 0
A33: urban | B33: biogas | C33: BAU | D33: M ppl | E33: =E69*E$73 -> 0 | F33: =F69*F$73 -> 0 | G33: =G69*G$73 -> 0 | H33: =H69*H$73 -> 0 | I33: =I69*I$73 -> 0 | J33: =J69*J$73 -> 0 | K33: =K69*K$73 -> 0 | L33: =L69*L$73 -> 0 | ... AS33: =AS69*AS$73 -> 0 | AT33: =Y33-T33 -> 0 | AU33: =AI33-Y33 -> 0
A34: urban | B34: other | C34: BAU | D34: M ppl | E34: =E70*E$73 -> 0.020548419 | F34: =F70*F$73 -> 0.019974224 | G34: =G70*G$73 -> 0.019285356 | H34: =H70*H$73 -> 0.018475557 | I34: =I70*I$73 -> 0.017538324 | J34: =J70*J$73 -> 0.016465996 | K34: =K70*K$73 -> 0.015249619 | L34: =L70*L$73 -> 0.013879364 | ... AS34: =AS70*AS$73 -> 0 | AT34: =Y34-T34 -> 0 | AU34: =AI34-Y34 -> 0
E36: Linear fit to survey data through 2024
A37: population | B37: Fuel | C37: Scenario | D37: unit | E37: 2010 | F37: 2011 | G37: 2012 | H37: 2013 | I37: 2014 | J37: 2015 | K37: 2016 | L37: 2017 | M37: 2018 | N37: 2019 | O37: 2020 | P37: 2021 | Q37: 2022 | R37: 2023 | S37: 2024 | T37: 2025 | U37: 2026 | V37: 2027 | W37: 2028 | X37: 2029 | Y37: 2030 | Z37: 2031 | AA37: 2032 | AB37: 2033 | AC37: 2034 | AD37: 2035 | AE37: 2036 | AF37: 2037 | AG37: 2038 | AH37: 2039 | AI37: 2040 | AJ37: 2041 | AK37: 2042 | AL37: 2043 | AM37: 2044 | AN37: 2045 | AO37: 2046 | AP37: 2047 | AQ37: 2048 | AR37: 2049 | AS37: 2050
A38: overall | B38: fuelwood | C38: BAU | D38: % of popl'n | E38: =(E49*E$72+E60*E$73)/E$71 -> 0.74604159 | F38: =(F49*F$72+F60*F$73)/F$71 -> 0.73233234 | G38: =(G49*G$72+G60*G$73)/G$71 -> 0.71863695 | H38: =(H49*H$72+H60*H$73)/H$71 -> 0.70495397 | I38: =(I49*I$72+I60*I$73)/I$71 -> 0.69128509 | J38: =(J49*J$72+J60*J$73)/J$71 -> 0.67763128 | K38: =(K49*K$72+K60*K$73)/K$71 -> 0.66399021 | L38: =(L49*L$72+L60*L$73)/L$71 -> 0.65035852 | ... AS38: =(AS49*AS$72+AS60*AS$73)/AS$71 -> 0.12575974
A39: overall | B39: charcoal | C39: BAU | D39: % of popl'n | E39: =(E50*E$72+E61*E$73)/E$71 -> 0.20032929 | F39: =(F50*F$72+F61*F$73)/F$71 -> 0.21533563 | G39: =(G50*G$72+G61*G$73)/G$71 -> 0.23035557 | H39: =(H50*H$72+H61*H$73)/H$71 -> 0.24539042 | I39: =(I50*I$72+I61*I$73)/I$71 -> 0.26043883 | J39: =(J50*J$72+J61*J$73)/J$71 -> 0.27550003 | K39: =(K50*K$72+K61*K$73)/K$71 -> 0.29057611 | L39: =(L50*L$72+L61*L$73)/L$71 -> 0.30567011 | ... AS39: =(AS50*AS$72+AS61*AS$73)/AS$71 -> 0.82653837
A40: overall | B40: Imp_fuelwood | C40: BAU | D40: % of popl'n | E40: =(E51*E$72+E62*E$73)/E$71 -> 0 | F40: =(F51*F$72+F62*F$73)/F$71 -> 0 | G40: =(G51*G$72+G62*G$73)/G$71 -> 0 | H40: =(H51*H$72+H62*H$73)/H$71 -> 0 | I40: =(I51*I$72+I62*I$73)/I$71 -> 0.00029284984 | J40: =(J51*J$72+J62*J$73)/J$71 -> 0.00093473778 | K40: =(K51*K$72+K62*K$73)/K$71 -> 0.0015918802 | L40: =(L51*L$72+L62*L$73)/L$71 -> 0.0022643655 | ... AS40: =(AS51*AS$72+AS62*AS$73)/AS$71 -> 0.031418241
A41: overall | B41: Imp_charcoal | C41: BAU | D41: % of popl'n | E41: =(E52*E$72+E63*E$73)/E$71 -> 0 | F41: =(F52*F$72+F63*F$73)/F$71 -> 0 | G41: =(G52*G$72+G63*G$73)/G$71 -> 0 | H41: =(H52*H$72+H63*H$73)/H$71 -> 0 | I41: =(I52*I$72+I63*I$73)/I$71 -> 9.7616614e-05 | J41: =(J52*J$72+J63*J$73)/J$71 -> 0.00031157926 | K41: =(K52*K$72+K63*K$73)/K$71 -> 0.00053062672 | L41: =(L52*L$72+L63*L$73)/L$71 -> 0.00075478851 | ... AS41: =(AS52*AS$72+AS63*AS$73)/AS$71 -> 0.010472747
...

Sheet BAU_Fuel_cons
A1: Mass/vol | B1: Fuel | C1: Scenario | D1: unit | E1: 2010 | F1: 2011 | G1: 2012 | H1: 2013 | I1: 2014 | J1: 2015 | K1: 2016 | L1: 2017 | M1: 2018 | N1: 2019 | O1: 2020 | P1: 2021 | Q1: 2022 | R1: 2023 | S1: 2024 | T1: 2025 | U1: 2026 | V1: 2027 | W1: 2028 | X1: 2029 | Y1: 2030 | Z1: 2031 | AA1: 2032 | AB1: 2033 | AC1: 2034 | AD1: 2035 | AE1: 2036 | AF1: 2037 | AG1: 2038 | AH1: 2039 | AI1: 2040 | AJ1: 2041 | AK1: 2042 | AL1: 2043 | AM1: 2044 | AN1: 2045 | AO1: 2046 | AP1: 2047 | AQ1: 2048 | AR1: 2049 | AS1: 2050 | AT1: For indexing | BD1: 2020 | BE1: 2025 | BF1: 2030 | BG1: 2035 | BH1: 2040 | BI1: 2045 | BJ1: 2050
A2: overall | B2: fuelwood | C2: BAU | D2: Mtons | E2: =SUM(E13,E24) -> 8.1533542 | F2: =SUM(F13,F24) -> 8.2889675 | G2: =SUM(G13,G24) -> 8.4207242 | H2: =SUM(H13,H24) -> 8.5487708 | I2: =SUM(I13,I24) -> 8.6735465 | J2: =SUM(J13,J24) -> 8.7952043 | K2: =SUM(K13,K24) -> 8.9133322 | L2: =SUM(L13,L24) -> 9.0271451 | ... AS2: =SUM(AS13,AS24) -> 4.1799752 | AT2: =_xlfn.TEXTJOIN("_",,A2,B2) -> overall_fuelwood | BC2: fuelwood | BD2: =_xlfn.XLOOKUP(BD$1,$N$1:$AS$1,$N4:$AS4)+_xlfn.XLOOKUP(BD$1,$N$1:$AS$1,$N2:$AS2) -> 9.3749296 | BE2: =_xlfn.XLOOKUP(BE$1,$N$1:$AS$1,$N4:$AS4)+_xlfn.XLOOKUP(BE$1,$N$1:$AS$1,$N2:$AS2) -> 9.70797 | BF2: =_xlfn.XLOOKUP(BF$1,$N$1:$AS$1,$N4:$AS4)+_xlfn.XLOOKUP(BF$1,$N$1:$AS$1,$N2:$AS2) -> 9.4542112 | BG2: =_xlfn.XLOOKUP(BG$1,$N$1:$AS$1,$N4:$AS4)+_xlfn.XLOOKUP(BG$1,$N$1:$AS$1,$N2:$AS2) -> 8.8405041 | BH2: =_xlfn.XLOOKUP(BH$1,$N$1:$AS$1,$N4:$AS4)+_xlfn.XLOOKUP(BH$1,$N$1:$AS$1,$N2:$AS2) -> 7.862165 | BI2: =_xlfn.XLOOKUP(BI$1,$N$1:$AS$1,$N4:$AS4)+_xlfn.XLOOKUP(BI$1,$N$1:$AS$1,$N2:$AS2) -> 6.5143436 | BJ2: =_xlfn.XLOOKUP(BJ$1,$N$1:$AS$1,$N4:$AS4)+_xlfn.XLOOKUP(BJ$1,$N$1:$AS$1,$N2:$AS2) -> 4.7973435
A3: overall | B3: charcoal | C3: BAU | D3: Mtons | E3: =SUM(E14,E25) -> 0.64716971 | F3: =SUM(F14,F25) -> 0.72045784 | G3: =SUM(G14,G25) -> 0.79788273 | H3: =SUM(H14,H25) -> 0.87963187 | I3: =SUM(I14,I25) -> 0.96593011 | J3: =SUM(J14,J25) -> 1.056999 | K3: =SUM(K14,K25) -> 1.1530251 | L3: =SUM(L14,L25) -> 1.2541544 | ... AS3: =SUM(AS14,AS25) -> 8.1207388 | AT3: =_xlfn.TEXTJOIN("_",,A3,B3) -> overall_charcoal | BB3: wood eq | BC3: charcoal | BD3: =6*(_xlfn.XLOOKUP(BD$1,$N$1:$AS$1,$N5:$AS5)+_xlfn.XLOOKUP(BD$1,$N$1:$AS$1,$N3:$AS3)) -> 9.5631076 | BE3: =6*(_xlfn.XLOOKUP(BE$1,$N$1:$AS$1,$N5:$AS5)+_xlfn.XLOOKUP(BE$1,$N$1:$AS$1,$N3:$AS3)) -> 13.701727 | BF3: =6*(_xlfn.XLOOKUP(BF$1,$N$1:$AS$1,$N5:$AS5)+_xlfn.XLOOKUP(BF$1,$N$1:$AS$1,$N3:$AS3)) -> 19.051219 | BG3: =6*(_xlfn.XLOOKUP(BG$1,$N$1:$AS$1,$N5:$AS5)+_xlfn.XLOOKUP(BG$1,$N$1:$AS$1,$N3:$AS3)) -> 25.272913 | BH3: =6*(_xlfn.XLOOKUP(BH$1,$N$1:$AS$1,$N5:$AS5)+_xlfn.XLOOKUP(BH$1,$N$1:$AS$1,$N3:$AS3)) -> 32.379752 | BI3: =6*(_xlfn.XLOOKUP(BI$1,$N$1:$AS$1,$N5:$AS5)+_xlfn.XLOOKUP(BI$1,$N$1:$AS$1,$N3:$AS3)) -> 40.359121 | BJ3: =6*(_xlfn.XLOOKUP(BJ$1,$N$1:$AS$1,$N5:$AS5)+_xlfn.XLOOKUP(BJ$1,$N$1:$AS$1,$N3:$AS3)) -> 49.136011
A4: overall | B4: Imp_fuelwood | C4: BAU | D4: Mtons | E4: =SUM(E15,E26) -> 0 | F4: =SUM(F15,F26) -> 0 | G4: =SUM(G15,G26) -> 0 | H4: =SUM(H15,H26) -> 0 | I4: =SUM(I15,I26) -> 0.0021722758 | J4: =SUM(J15,J26) -> 0.0071725358 | K4: =SUM(K15,K26) -> 0.012633371 | L4: =SUM(L15,L26) -> 0.018581235 | ... AS4: =SUM(AS15,AS26) -> 0.61736838 | AT4: =_xlfn.TEXTJOIN("_",,A4,B4) -> overall_Imp_fuelwood | BC4: Gas | BD4: =_xlfn.XLOOKUP(BD$1,$N$1:$AS$1,$N6:$AS6) -> 0.0018381231 | BE4: =_xlfn.XLOOKUP(BE$1,$N$1:$AS$1,$N6:$AS6) -> 0.0031011586 | BF4: =_xlfn.XLOOKUP(BF$1,$N$1:$AS$1,$N6:$AS6) -> 0.0030188871 | BG4: =_xlfn.XLOOKUP(BG$1,$N$1:$AS$1,$N6:$AS6) -> 0.0027117983 | BH4: =_xlfn.XLOOKUP(BH$1,$N$1:$AS$1,$N6:$AS6) -> 0.0021381412 | BI4: =_xlfn.XLOOKUP(BI$1,$N$1:$AS$1,$N6:$AS6) -> 0.001250969 | BJ4: =_xlfn.XLOOKUP(BJ$1,$N$1:$AS$1,$N6:$AS6) -> 0
A5: overall | B5: Imp_charcoal | C5: BAU | D5: Mtons | E5: =SUM(E16,E27) -> 0 | F5: =SUM(F16,F27) -> 0 | G5: =SUM(G16,G27) -> 0 | H5: =SUM(H16,H27) -> 0 | I5: =SUM(I16,I27) -> 0.00024136398 | J5: =SUM(J16,J27) -> 0.00079694842 | K5: =SUM(K16,K27) -> 0.0014037078 | L5: =SUM(L16,L27) -> 0.0020645816 | ... AS5: =SUM(AS16,AS27) -> 0.068596487 | AT5: =_xlfn.TEXTJOIN("_",,A5,B5) -> overall_Imp_charcoal | BC5: kerosene | BD5: =_xlfn.XLOOKUP(BD$1,$N$1:$AS$1,$N7:$AS7) -> 0.00014109146 | BE5: =_xlfn.XLOOKUP(BE$1,$N$1:$AS$1,$N7:$AS7) -> 0 | BF5: =_xlfn.XLOOKUP(BF$1,$N$1:$AS$1,$N7:$AS7) -> 0 | BG5: =_xlfn.XLOOKUP(BG$1,$N$1:$AS$1,$N7:$AS7) -> 0 | BH5: =_xlfn.XLOOKUP(BH$1,$N$1:$AS$1,$N7:$AS7) -> 0 | BI5: =_xlfn.XLOOKUP(BI$1,$N$1:$AS$1,$N7:$AS7) -> 0 | BJ5: =_xlfn.XLOOKUP(BJ$1,$N$1:$AS$1,$N7:$AS7) -> 0
A6: overall | B6: Gas | C6: BAU | D6: Mtons | E6: =SUM(E17,E28) -> 0.00010031991 | F6: =SUM(F17,F28) -> 0.00010039494 | G6: =SUM(G17,G28) -> 0.00021283209 | H6: =SUM(H17,H28) -> 0.00036209909 | I6: =SUM(I17,I28) -> 0.00052507656 | J6: =SUM(J17,J28) -> 0.00070259249 | K6: =SUM(K17,K28) -> 0.0008954988 | L6: =SUM(L17,L28) -> 0.0011046466 | ... AS6: =SUM(AS17,AS28) -> 0 | AT6: =_xlfn.TEXTJOIN("_",,A6,B6) -> overall_Gas | BC6: electric | BD6: =_xlfn.XLOOKUP(BD$1,$N$1:$AS$1,$N8:$AS8) -> 0.30835623 | BE6: =_xlfn.XLOOKUP(BE$1,$N$1:$AS$1,$N8:$AS8) -> 0.29081508 | BF6: =_xlfn.XLOOKUP(BF$1,$N$1:$AS$1,$N8:$AS8) -> 0.28277446 | BG6: =_xlfn.XLOOKUP(BG$1,$N$1:$AS$1,$N8:$AS8) -> 0.25374543 | BH6: =_xlfn.XLOOKUP(BH$1,$N$1:$AS$1,$N8:$AS8) -> 0.19987619 | BI6: =_xlfn.XLOOKUP(BI$1,$N$1:$AS$1,$N8:$AS8) -> 0.11683771 | BJ6: =_xlfn.XLOOKUP(BJ$1,$N$1:$AS$1,$N8:$AS8) -> 0
A7: overall | B7: kerosene | C7: BAU | D7: Mtons | E7: =SUM(E18,E29) -> 0.00033293868 | F7: =SUM(F18,F29) -> 0.00032359649 | G7: =SUM(G18,G29) -> 0.00031239257 | H7: =SUM(H18,H29) -> 0.0002992253 | I7: =SUM(I18,I29) -> 0.00028398911 | J7: =SUM(J18,J29) -> 0.00026655958 | K7: =SUM(K18,K29) -> 0.00024679143 | L7: =SUM(L18,L29) -> 0.00022452511 | ... AS7: =SUM(AS18,AS29) -> 0 | AT7: =_xlfn.TEXTJOIN("_",,A7,B7) -> overall_kerosene | BC7: pellets | BD7: =_xlfn.XLOOKUP(BD$1,$N$1:$AS$1,$N9:$AS9) -> 0 | BE7: =_xlfn.XLOOKUP(BE$1,$N$1:$AS$1,$N9:$AS9) -> 0 | BF7: =_xlfn.XLOOKUP(BF$1,$N$1:$AS$1,$N9:$AS9) -> 0 | BG7: =_xlfn.XLOOKUP(BG$1,$N$1:$AS$1,$N9:$AS9) -> 0 | BH7: =_xlfn.XLOOKUP(BH$1,$N$1:$AS$1,$N9:$AS9) -> 0 | BI7: =_xlfn.XLOOKUP(BI$1,$N$1:$AS$1,$N9:$AS9) -> 0 | BJ7: =_xlfn.XLOOKUP(BJ$1,$N$1:$AS$1,$N9:$AS9) -> 0
A8: overall | B8: electric | C8: BAU | D8: GWh | E8: =SUM(E19,E30) -> 0.29878207 | F8: =SUM(F19,F30) -> 0.30224992 | G8: =SUM(G19,G30) -> 0.30524228 | H8: =SUM(H19,H30) -> 0.30773827 | I8: =SUM(I19,I30) -> 0.30972077 | J8: =SUM(J19,J30) -> 0.31116114 | K8: =SUM(K19,K30) -> 0.3120141 | L8: =SUM(L19,L30) -> 0.31222153 | ... AS8: =SUM(AS19,AS30) -> 0 | AT8: =_xlfn.TEXTJOIN("_",,A8,B8) -> overall_electric | BC8: ethanol | BD8: =_xlfn.XLOOKUP(BD$1,$N$1:$AS$1,$N10:$AS10) -> 0 | BE8: =_xlfn.XLOOKUP(BE$1,$N$1:$AS$1,$N10:$AS10) -> 0 | BF8: =_xlfn.XLOOKUP(BF$1,$N$1:$AS$1,$N10:$AS10) -> 0 | BG8: =_xlfn.XLOOKUP(BG$1,$N$1:$AS$1,$N10:$AS10) -> 0 | BH8: =_xlfn.XLOOKUP(BH$1,$N$1:$AS$1,$N10:$AS10) -> 0 | BI8: =_xlfn.XLOOKUP(BI$1,$N$1:$AS$1,$N10:$AS10) -> 0 | BJ8: =_xlfn.XLOOKUP(BJ$1,$N$1:$AS$1,$N10:$AS10) -> 0
A9: overall | B9: pellets | C9: BAU | D9: Mtons | E9: =SUM(E20,E31) -> 0 | F9: =SUM(F20,F31) -> 0 | G9: =SUM(G20,G31) -> 0 | H9: =SUM(H20,H31) -> 0 | I9: =SUM(I20,I31) -> 0 | J9: =SUM(J20,J31) -> 0 | K9: =SUM(K20,K31) -> 0 | L9: =SUM(L20,L31) -> 0 | ... AS9: =SUM(AS20,AS31) -> 0 | AT9: =_xlfn.TEXTJOIN("_",,A9,B9) -> overall_pellets | BC9: biogas | BD9: =_xlfn.XLOOKUP(BD$1,$N$1:$AS$1,$N11:$AS11) -> 0 | BE9: =_xlfn.XLOOKUP(BE$1,$N$1:$AS$1,$N11:$AS11) -> 0 | BF9: =_xlfn.XLOOKUP(BF$1,$N$1:$AS$1,$N11:$AS11) -> 0 | BG9: =_xlfn.XLOOKUP(BG$1,$N$1:$AS$1,$N11:$AS11) -> 0 | BH9: =_xlfn.XLOOKUP(BH$1,$N$1:$AS$1,$N11:$AS11) -> 0 | BI9: =_xlfn.XLOOKUP(BI$1,$N$1:$AS$1,$N11:$AS11) -> 0 | BJ9: =_xlfn.XLOOKUP(BJ$1,$N$1:$AS$1,$N11:$AS11) -> 0
A10: overall | B10: ethanol | C10: BAU | D10: Mtons | E10: =SUM(E21,E32) -> 0 | F10: =SUM(F21,F32) -> 0 | G10: =SUM(G21,G32) -> 0 | H10: =SUM(H21,H32) -> 0 | I10: =SUM(I21,I32) -> 0 | J10: =SUM(J21,J32) -> 0 | K10: =SUM(K21,K32) -> 0 | L10: =SUM(L21,L32) -> 0 | ... AS10: =SUM(AS21,AS32) -> 0 | AT10: =_xlfn.TEXTJOIN("_",,A10,B10) -> overall_ethanol
A11: overall | B11: biogas | C11: BAU | D11: Mtons | E11: =SUM(E22,E33) -> 0 | F11: =SUM(F22,F33) -> 0 | G11: =SUM(G22,G33) -> 0 | H11: =SUM(H22,H33) -> 0 | I11: =SUM(I22,I33) -> 0 | J11: =SUM(J22,J33) -> 0 | K11: =SUM(K22,K33) -> 0 | L11: =SUM(L22,L33) -> 0 | ... AS11: =SUM(AS22,AS33) -> 0 | AT11: =_xlfn.TEXTJOIN("_",,A11,B11) -> overall_biogas | BB11: Total woodfuel | BC11: BAU | BD11: =SUM(BD2:BD3) -> 18.938037 | BE11: =SUM(BE2:BE3) -> 23.409697 | BF11: =SUM(BF2:BF3) -> 28.50543 | BG11: =SUM(BG2:BG3) -> 34.113417 | BH11: =SUM(BH2:BH3) -> 40.241917 | BI11: =SUM(BI2:BI3) -> 46.873465 | BJ11: =SUM(BJ2:BJ3) -> 53.933355
A12: overall | B12: other | C12: BAU | D12: Mtons | E12: =SUM(E23,E34) -> 0 | F12: =SUM(F23,F34) -> 0 | G12: =SUM(G23,G34) -> 0 | H12: =SUM(H23,H34) -> 0 | I12: =SUM(I23,I34) -> 0 | J12: =SUM(J23,J34) -> 0 | K12: =SUM(K23,K34) -> 0 | L12: =SUM(L23,L34) -> 0 | ... AS12: =SUM(AS23,AS34) -> 0 | AT12: =_xlfn.TEXTJOIN("_",,A12,B12) -> overall_other | BC12: NICCS | BD12: =SUM(NICCS_Fuel_cons!AU2:AU3) -> 18.938037 | BE12: =SUM(NICCS_Fuel_cons!AV2:AV3) -> 23.409697 | BF12: =SUM(NICCS_Fuel_cons!AW2:AW3) -> 20.498862 | BG12: =SUM(NICCS_Fuel_cons!AX2:AX3) -> 15.611967 | BH12: =SUM(NICCS_Fuel_cons!AY2:AY3) -> 8.524239 | BI12: =SUM(NICCS_Fuel_cons!AZ2:AZ3) -> 9.2974491 | BJ12: =SUM(NICCS_Fuel_cons!BA2:BA3) -> 10.03292
A13: rural | B13: fuelwood | C13: BAU | D13: Mtons | E13: =BAU_Scenario!E13*_xlfn.XLOOKUP($B13,params!$O$2:$O$12,params!$P$2:$P$12,0) -> 6.9722869 | F13: =BAU_Scenario!F13*_xlfn.XLOOKUP($B13,params!$O$2:$O$12,params!$P$2:$P$12,0) -> 7.0874977 | G13: =BAU_Scenario!G13*_xlfn.XLOOKUP($B13,params!$O$2:$O$12,params!$P$2:$P$12,0) -> 7.2003031 | H13: =BAU_Scenario!H13*_xlfn.XLOOKUP($B13,params!$O$2:$O$12,params!$P$2:$P$12,0) -> 7.3109177 | I13: =BAU_Scenario!I13*_xlfn.XLOOKUP($B13,params!$O$2:$O$12,params!$P$2:$P$12,0) -> 7.4198339 | J13: =BAU_Scenario!J13*_xlfn.XLOOKUP($B13,params!$O$2:$O$12,params!$P$2:$P$12,0) -> 7.5273014 | K13: =BAU_Scenario!K13*_xlfn.XLOOKUP($B13,params!$O$2:$O$12,params!$P$2:$P$12,0) -> 7.6330691 | L13: =BAU_Scenario!L13*_xlfn.XLOOKUP($B13,params!$O$2:$O$12,params!$P$2:$P$12,0) -> 7.7365648 | ... AS13: =BAU_Scenario!AS13*_xlfn.XLOOKUP($B13,params!$O$2:$O$12,params!$P$2:$P$12,0) -> 4.1799752 | AT13: =_xlfn.TEXTJOIN("_",,A13,B13) -> rural_fuelwood | BC13: % diff | BD13: =(BD12-BD11)/BD11 -> 0 | BE13: =(BE12-BE11)/BE11 -> -3.0352496e-16 | BF13: =(BF12-BF11)/BF11 -> -0.28087869 | BG13: =(BG12-BG11)/BG11 -> -0.54235114 | BH13: =(BH12-BH11)/BH11 -> -0.78817512 | BI13: =(BI12-BI11)/BI11 -> -0.80164792 | BJ13: =(BJ12-BJ11)/BJ11 -> -0.8139756
